<?xml version="1.0" ?>

<robot name="ur5_with_torch" xmlns:xacro="http://ros.org/wiki/xacro">

  <link name="base_link">
    <visual>
      <geometry>
        <mesh filename="../meshes/visual/base.obj"/>
      </geometry>
      <material name="Black">
        <color rgba="0.0 0.0 0 0.25"/>
      </material>
    </visual> 
  </link>

  <joint name="shoulder_pan_joint" type="revolute">
    <parent link="base_link"/>
    <child link="shoulder_link"/>
    <origin rpy="0.0 0.0 3.14" xyz="0.0 0.0 0.089159"/>
    <axis xyz="0 0 1"/>
    <limit effort="300.0" lower="-3.14159265359" upper="3.14159265359" velocity="10"/>
  </joint>
  <link name="shoulder_link">
    <visual>
      <geometry>
        <mesh filename="../meshes/visual/shoulder.obj"/>
      </geometry>
      <material name="Snow">
        <color rgba="1.0 0.98039 0.98039 0.25"/>
      </material>
    </visual>
  </link>
  <joint name="shoulder_lift_joint" type="revolute">
    <parent link="shoulder_link"/>
    <child link="upper_arm_link"/>
    <origin rpy="0.0 1.6 0.0" xyz="0.0 0.13585 0.0"/>
    <axis xyz="0 1 0"/>
    <limit effort="300.0" lower="-3.14159265359" upper="3.14159265359" velocity="10"/>
  </joint>
  <link name="upper_arm_link">
    <visual>
      <geometry>
        <mesh filename="../meshes/visual/upperarm.obj"/>
      </geometry>
      <material name="Black">
        <color rgba="0.0 0.0 0 0.25"/>
      </material>
    </visual>
  </link>
  <joint name="elbow_joint" type="revolute">
    <parent link="upper_arm_link"/>
    <child link="forearm_link"/>
    <origin rpy="0.0 0.0 0.0" xyz="0.0 -0.1197 0.425"/>
    <axis xyz="0 1 0"/>
    <limit effort="300.0" lower="-3.14159265359" upper="3.14159265359" velocity="10"/>
  </joint>
  <link name="forearm_link">
    <visual>
      <geometry>
        <mesh filename="../meshes/visual/forearm.obj"/>
      </geometry>
      <material name="Snow">
        <color rgba="1.0 0.98039 0.98039 0.25"/>
      </material>
    </visual>
  </link>
  <joint name="wrist_1_joint" type="revolute">
    <parent link="forearm_link"/>
    <child link="wrist_1_link"/>
    <origin rpy="0.0 1.57079632679 0.0" xyz="0.0 0.0 0.39225"/>
    <axis xyz="0 1 0"/>
    <limit effort="300.0" lower="-3.14159265359" upper="3.14159265359" velocity="10"/>
  </joint>
  <link name="wrist_1_link">
    <visual>

      <geometry>
        <mesh filename="../meshes/visual/wrist1.obj"/>
      </geometry>
      <material name="Black">
        <color rgba="0.0 0.0 0 0.25"/>
      </material>
    </visual>
  </link>
  <joint name="wrist_2_joint" type="revolute">
    <parent link="wrist_1_link"/>
    <child link="wrist_2_link"/>
    <origin rpy="0.0 0.0 0.0" xyz="0.0 0.093 0.0"/>
    <axis xyz="0 0 1"/>
    <limit effort="300.0" lower="-3.14159265359" upper="3.14159265359" velocity="10"/>
  </joint>
  <link name="wrist_2_link">
    <visual>
      <geometry>
        <mesh filename="../meshes/visual/wrist2.obj"/>
      </geometry>
      <material name="Snow">
        <color rgba="1.0 0.98039 0.98039 0.25"/>
      </material>
    </visual>
  </link>
  <joint name="wrist_3_joint" type="revolute">
    <parent link="wrist_2_link"/>
    <child link="wrist_3_link"/>
    <origin rpy="0.0 0.0 0.0" xyz="0.0 0.0 0.09465"/>
    <axis xyz="0 1 0"/>
    <limit effort="300.0" lower="-3.14159265359" upper="3.14159265359" velocity="10"/>
  </joint>
  <link name="wrist_3_link">
    <visual>
      <geometry>
        <mesh filename="../meshes/visual/wrist3.obj"/>
      </geometry>
      <material name="Black">
        <color rgba="0.0 0.0 0 0.25"/>
      </material>
    </visual>
  </link>
  
  <joint name="ee_fixed_joint" type="fixed">
    <parent link="wrist_3_link"/>
    <child link="ee_link"/>
    <origin rpy="1.57 0.0 3.14" xyz="0.0 0.13 0.0"/>
  </joint>
  
  <link name="ee_link">
    <visual>
      <geometry>
        <cylinder length="0.04" radius="0.006"/>
      </geometry>
      <origin rpy="0 0 0" xyz="0.0 0.0 -0.03"/>
      <material name="Green">
        <color rgba="0.0 0.98039 0.48039 1.0"/>
      </material>
    </visual>
  </link>


  <!-- connect arm to world -->
  <link name="world"/>
  <joint name="world_joint" type="fixed">
    <parent link="world"/>
    <child link="base_link"/>
    <origin rpy="0.0 0.0 0" xyz="0.0 0.0 0.0"/>
  </joint>
</robot>
